<?xml version="1.0"?>
<robot xmlns:xacro="http://www.ros.org/wiki/xacro">

    <xacro:property name="arm_mass" value="5.0"/>
    <xacro:property name="arm_link_length" value="0.5" />
    <xacro:property name="arm_link_radius" value="0.1" />
    
    <xacro:property name="arm_base_length" value="0.3" />
    <xacro:property name="arm_base_width" value="0.3" />
    <xacro:property name="arm_base_height" value="0.1" />
    
    <link name="base_link">
        <visual>
            <geometry>
                <box size="${arm_base_length} ${arm_base_width} 
                        ${arm_base_height}" />
            </geometry>
            <origin xyz="0 0 0" rpy="0 0 0" />
            <material name="grey" />
        </visual>
    </link>

    <link name="bicep_link">
        <visual>
            <geometry>
                <cylinder radius="${arm_link_radius}" length="${arm_link_length}" />
            </geometry>
            <origin xyz="0 0 0" rpy="0 0 0" />
            <material name="yellow" />
        </visual>
    </link>

    <joint name="base_bicep_joint" type="revolute">
        <parent name="base_link" />
        <child name="bicep_link" />
        <origin xyz="0 0 0" rpy="0 0 0" />
        <axis xyz="0 1 0" />
        <limit upper="${pi}" lower="${pi / 2.0}" effort="100" velocity="100" />
    </joint>

    <link name="forearm_link">
        <visual>
            <geometry>
                <cylinder radius="${arm_link_radius}" length="${arm_link_length}" />
            </geometry>
            <origin xyz="0 0 0" rpy="0 0 0" />
            <material name="yellow" />
        </visual>
    </link>

    <joint name="bicep_forearm_joint" type="revolute">
        <parent name="bicep_link" />
        <child name="forearm_link" />
        <origin xyz="0 0 0" rpy="0 0 0" />
        <axis xyz="0 1 0" />
        <limit upper="${pi}" lower="${pi / 2.0}" effort="100" velocity="100" />
    </joint>

</robot>